Workbook

Sheet Test Scenarios
A1: Test Scenario ID | B1: Reference | C1: Test Scenario Description | D1: Priority | E1: Number of Test Cases
A2: TS_001 | B2: FRS | C2: Register Functionality | D2: P0 | E2: 27
A3: TS_002 | B3: FRS | C3: Login Functionality | D3: P0 | E3: 23
A4: TS_003 | B4: FRS | C4: Logout Functionality | D4: P0 | E4: 11
A5: TS_004 | B5: FRS | C5: Forgot Password | D5: P2 | E5: 25
A6: TS_005 | B6: FRS | C6: Search Functionality | D6: P1 | E6: 22
A7: TS_006 | B7: FRS | C7: Product Compare | D7: P4 | E7: 24
A8: TS_007 | B8: FRS | C8: Product Display Page | D8: P1 | E8: 37
A9: TS_008 | B9: FRS | C9: Add to Cart | D9: P1 | E9: 9
A10: TS_009 | B10: FRS | C10: Wish List | D10: P4 | E10: 21
A11: TS_010 | B11: FRS | C11: Shopping Cart | D11: P1 | E11: 33
A12: TS_011 | B12: FRS | C12: Home Page | D12: P2 | E12: 10
A13: TS_012 | B13: FRS | C13: Checkout | D13: P1 | E13: 20
A14: TS_013 | B14: FRS | C14: My Account | D14: P2 | E14: 9
C15: TOTAL TEST CASES | E15: =SUM(E2:E14) -> 271

Sheet Test Cases
A1: Test Case ID | B1: Test Scenario ID | C1: Reference | D1: Module | E1: Test Case Title | F1: Preconditions | G1: Test Steps | H1: Test Data | I1: Expected Result | J1: Priority | K1: Test Type | L1: Status | M1: Actual Result | N1: Defect ID | O1: Executed By | P1: Execution Date
A2: TC_0001 | B2: TS_001 | C2: FRS | D2: Register | E2: Register with valid mandatory data | F2: User is on the Registration page and is not logged in. | G2: 1. Navigate to the Registration page. 2. Enter a valid first name, last name, and a unique email address. 3. Enter a password that meets complexity rules. 4. Re-enter the same password in the Confirm Password field. 5. Check the 'I agree to Terms and Conditions' checkbox. 6. Click the Register button. | H2: First Name: Sarah | Last Name: Ahmed | Email: sarah.ahmed01@example.com | Password: Passw0rd!23 | I2: Account is created successfully, a confirmation message is shown, and the user is redirected to the login page or homepage as a logged-in user. | J2: P0 | K2: Positive | L2: Pass | M2: Account created successfully; redirected to homepage as logged-in user. | O2: Ali Hassan | P2: 2026-09-15
A3: TC_0002 | B3: TS_001 | C3: FRS | D3: Register | E3: Register with empty First Name field | F3: User is on the Registration page. | G3: 1. Leave the First Name field empty. 2. Fill in all other required fields with valid data. 3. Click the Register button. | H3: First Name: (empty) | Last Name: Hassan | Email: hassan.t@example.com | Password: Passw0rd!23 | I3: Registration is blocked and an inline validation message 'First name is required' is displayed under the First Name field. | J3: P0 | K3: Negative - Required Field Validation | L3: Pass | M3: Validation message 'First name is required' displayed as expected. | O3: Mona Fathy | P3: 2026-09-15
A4: TC_0003 | B4: TS_001 | C4: FRS | D4: Register | E4: Register with empty Last Name field | F4: User is on the Registration page. | G4: 1. Leave the Last Name field empty. 2. Fill in all other required fields with valid data. 3. Click the Register button. | H4: First Name: Omar | Last Name: (empty) | Email: omar.k@example.com | Password: Passw0rd!23 | I4: Registration is blocked and an inline validation message 'Last name is required' is displayed under the Last Name field. | J4: P0 | K4: Negative - Required Field Validation | L4: Pass
A5: TC_0004 | B5: TS_001 | C5: FRS | D5: Register | E5: Register with empty Email field | F5: User is on the Registration page. | G5: 1. Leave the Email field empty. 2. Fill in all other required fields with valid data. 3. Click the Register button. | H5: Email: (empty) | I5: Registration is blocked and an inline validation message 'Email is required' is displayed under the Email field. | J5: P0 | K5: Negative - Required Field Validation | L5: Pass
A6: TC_0005 | B6: TS_001 | C6: FRS | D6: Register | E6: Register with empty Password field | F6: User is on the Registration page. | G6: 1. Leave the Password field empty. 2. Fill in all other required fields with valid data. 3. Click the Register button. | H6: Password: (empty) | I6: Registration is blocked and an inline validation message 'Password is required' is displayed under the Password field. | J6: P0 | K6: Negative - Required Field Validation | L6: Pass
A7: TC_0006 | B7: TS_001 | C7: FRS | D7: Register | E7: Register with empty Confirm Password field | F7: User is on the Registration page. | G7: 1. Enter a valid password in the Password field. 2. Leave the Confirm Password field empty. 3. Click the Register button. | H7: Password: Passw0rd!23 | Confirm Password: (empty) | I7: Registration is blocked and a validation message 'Please confirm your password' is displayed. | J7: P0 | K7: Negative - Required Field Validation | L7: Pass
A8: TC_0007 | B8: TS_001 | C8: FRS | D8: Register | E8: Register with invalid email format - missing @ symbol | F8: User is on the Registration page. | G8: 1. Fill in all fields with valid data. 2. Enter an email address without an '@' symbol. 3. Click the Register button. | H8: Email: sarahexample.com | I8: Registration is blocked and a validation message 'Please enter a valid email address' is displayed. | J8: P0 | K8: Negative - Field Format Validation | L8: Pass
A9: TC_0008 | B9: TS_001 | C9: FRS | D9: Register | E9: Register with invalid email format - missing domain | F9: User is on the Registration page. | G9: 1. Fill in all fields with valid data. 2. Enter an email address without a domain after the '@' symbol. 3. Click the Register button. | H9: Email: sarah.ahmed@ | I9: Registration is blocked and a validation message 'Please enter a valid email address' is displayed. | J9: P0 | K9: Negative - Field Format Validation | L9: Pass
A10: TC_0009 | B10: TS_001 | C10: FRS | D10: Register | E10: Register with an already registered email address | F10: An account already exists with the email 'existing.user@example.com'. | G10: 1. Navigate to the Registration page. 2. Fill in the form using an email address that is already registered. 3. Click the Register button. | H10: Email: existing.user@example.com | I10: Registration is blocked and an error message 'An account with this email already exists' is displayed, with a suggestion to log in instead. | J10: P0 | K10: Negative - Business Rule Validation | L10: Fail | M10: Registration succeeded with a duplicate email; no error message was shown. | N10: BUG_001 | O10: Mona Fathy | P10: 2026-09-15
A11: TC_0010 | B11: TS_001 | C11: FRS | D11: Register | E11: Register with password shorter than minimum allowed length | F11: User is on the Registration page. Minimum password length is 8 characters. | G11: 1. Fill in all fields with valid data. 2. Enter a password with 7 characters. 3. Click the Register button. | H11: Password: Pas1!aB (7 characters) | I11: Registration is blocked and a validation message 'Password must be at least 8 characters long' is displayed. | J11: P0 | K11: Boundary Value Analysis | L11: Not Run
A12: TC_0011 | B12: TS_001 | C12: FRS | D12: Register | E12: Register with password at exact minimum allowed length | F12: User is on the Registration page. Minimum password length is 8 characters. | G12: 1. Fill in all fields with valid data. 2. Enter a password with exactly 8 characters meeting complexity rules. 3. Click the Register button. | H12: Password: Pass1!aB (8 characters) | I12: Password is accepted and the account is registered successfully. | J12: P0 | K12: Boundary Value Analysis | L12: Not Run
A13: TC_0012 | B13: TS_001 | C13: FRS | D13: Register | E13: Register with password exceeding maximum allowed length | F13: User is on the Registration page. Maximum password length is 20 characters. | G13: 1. Fill in all fields with valid data. 2. Enter a password with 21 characters. 3. Click the Register button. | H13: Password: Passw0rd!23456789ABCX (21 characters) | I13: Registration is blocked and a validation message 'Password must not exceed 20 characters' is displayed. | J13: P0 | K13: Boundary Value Analysis | L13: Not Run
A14: TC_0013 | B14: TS_001 | C14: FRS | D14: Register | E14: Register with password missing an uppercase letter | F14: User is on the Registration page. | G14: 1. Fill in all fields with valid data. 2. Enter a password containing only lowercase letters, numbers, and symbols. 3. Click the Register button. | H14: Password: passw0rd!23 | I14: Registration is blocked and a validation message 'Password must contain at least one uppercase letter' is displayed. | J14: P0 | K14: Validation Testing | L14: Pass | M14: Password with missing uppercase letter correctly rejected. | O14: Ali Hassan | P14: 2026-09-15
A15: TC_0014 | B15: TS_001 | C15: FRS | D15: Register | E15: Register with password missing a numeric character | F15: User is on the Registration page. | G15: 1. Fill in all fields with valid data. 2. Enter a password without any digits. 3. Click the Register button. | H15: Password: Password!ABC | I15: Registration is blocked and a validation message 'Password must contain at least one number' is displayed. | J15: P0 | K15: Validation Testing | L15: Pass
A16: TC_0015 | B16: TS_001 | C16: FRS | D16: Register | E16: Register with password missing a special character | F16: User is on the Registration page. | G16: 1. Fill in all fields with valid data. 2. Enter a password containing only letters and numbers. 3. Click the Register button. | H16: Password: Passw0rd123 | I16: Registration is blocked and a validation message 'Password must contain at least one special character' is displayed. | J16: P0 | K16: Validation Testing | L16: Pass
A17: TC_0016 | B17: TS_001 | C17: FRS | D17: Register | E17: Register with mismatched Password and Confirm Password | F17: User is on the Registration page. | G17: 1. Fill in all fields with valid data. 2. Enter a valid password in the Password field. 3. Enter a different value in the Confirm Password field. 4. Click the Register button. | H17: Password: Passw0rd!23 | Confirm Password: Passw0rd!24 | I17: Registration is blocked and a validation message 'Passwords do not match' is displayed. | J17: P0 | K17: Negative - Field Validation | L17: Pass
A18: TC_0017 | B18: TS_001 | C18: FRS | D18: Register | E18: Register with SQL injection payload in the Email field | F18: User is on the Registration page. | G18: 1. Fill in all other fields with valid data. 2. Enter a SQL injection payload in the Email field. 3. Click the Register button. | H18: Email: ' OR '1'='1'; DROP TABLE Users;-- | I18: Input is rejected by client-side/server-side validation as an invalid email; no database error is exposed and no data is compromised. | J18: P0 | K18: Security Testing | L18: Pass
A19: TC_0018 | B19: TS_001 | C19: FRS | D19: Register | E19: Register with script tag in the First Name field (XSS attempt) | F19: User is on the Registration page. | G19: 1. Fill in all other fields with valid data. 2. Enter a script tag as the First Name. 3. Click the Register button. | H19: First Name: <script>alert('xss')</script> | I19: The script is not executed and is either rejected with a validation message or safely encoded/sanitized when stored and displayed. | J19: P0 | K19: Security Testing | L19: Pass
A20: TC_0019 | B20: TS_001 | C20: FRS | D20: Register | E20: Register with leading and trailing spaces in the Email field | F20: User is on the Registration page. | G20: 1. Fill in all fields with valid data. 2. Enter an email address with leading and trailing spaces. 3. Click the Register button. | H20: Email: ' sarah.ahmed01@example.com ' | I20: The application trims the spaces automatically and registers the account successfully with the cleaned email value. | J20: P0 | K20: Equivalence Partitioning | L20: Pass
A21: TC_0020 | B21: TS_001 | C21: FRS | D21: Register | E21: Register with numeric characters in the First Name field | F21: User is on the Registration page. | G21: 1. Fill in all fields with valid data. 2. Enter numeric characters in the First Name field. 3. Click the Register button. | H21: First Name: 12345 | I21: Registration is blocked and a validation message 'First name must contain only letters' is displayed. | J21: P0 | K21: Validation Testing | L21: Pass
A22: TC_0021 | B22: TS_001 | C22: FRS | D22: Register | E22: Register with special characters in the First Name field | F22: User is on the Registration page. | G22: 1. Fill in all fields with valid data. 2. Enter special characters in the First Name field. 3. Click the Register button. | H22: First Name: @#$%^& | I22: Registration is blocked and a validation message 'First name contains invalid characters' is displayed. | J22: P0 | K22: Validation Testing | L22: Pass
A23: TC_0022 | B23: TS_001 | C23: FRS | D23: Register | E23: Register without accepting Terms and Conditions | F23: User is on the Registration page and the Terms and Conditions checkbox is unchecked by default. | G23: 1. Fill in all required fields with valid data. 2. Leave the 'I agree to Terms and Conditions' checkbox unchecked. 3. Click the Register button. | H23: All fields valid, Terms checkbox: unchecked | I23: Registration is blocked and a message 'You must accept the Terms and Conditions to continue' is displayed. | J23: P0 | K23: Business Rule Validation | L23: Pass
A24: TC_0023 | B24: TS_001 | C24: FRS | D24: Register | E24: Register with a valid phone number format | F24: User is on the Registration page and the form includes an optional/required Phone Number field. | G24: 1. Fill in all required fields with valid data. 2. Enter a valid phone number in the Phone Number field. 3. Click the Register button. | H24: Phone: +201012345678 | I24: The phone number is accepted and the account is registered successfully. | J24: P0 | K24: Positive | L24: Pass
A25: TC_0024 | B25: TS_001 | C25: FRS | D25: Register | E25: Register with an invalid phone number format | F25: User is on the Registration page. | G25: 1. Fill in all required fields with valid data. 2. Enter an invalid phone number containing letters. 3. Click the Register button. | H25: Phone: 12A-BC-4567 | I25: Registration is blocked and a validation message 'Please enter a valid phone number' is displayed. | J25: P0 | K25: Negative - Field Format Validation | L25: Pass
A26: TC_0025 | B26: TS_001 | C26: FRS | D26: Register | E26: Verify duplicate submission is prevented on double-click of Register button | F26: User is on the Registration page with all fields filled with valid data. | G26: 1. Fill in all required fields with valid, unique data. 2. Rapidly double-click the Register button before the page responds. | H26: All fields valid and unique | I26: Only one account is created; the button is disabled or shows a loading state after the first click, preventing a duplicate submission/duplicate account. | J26: P0 | K26: Negative - Regression | L26: Pass | M26: Duplicate click prevented; only one account created. | O26: Youssef Adel | P26: 2026-09-16
A27: TC_0026 | B27: TS_001 | C27: FRS | D27: Register | E27: Verify navigation from Register page to Login page | F27: User is on the Registration page. | G27: 1. Locate the 'Already have an account? Login' link. 2. Click the link. | H27: N/A | I27: The user is navigated to the Login page successfully. | J27: P0 | K27: Navigation Testing | L27: Pass
A28: TC_0027 | B28: TS_001 | C28: FRS | D28: Register | E28: Verify Password field masks entered characters | F28: User is on the Registration page. | G28: 1. Click into the Password field. 2. Type a password. 3. Observe the displayed characters. | H28: Password: Passw0rd!23 | I28: Entered characters are masked (displayed as dots/asterisks) by default to protect the password from shoulder-surfing. | J28: P0 | K28: UI Testing | L28: Pass
A29: TC_0028 | B29: TS_002 | C29: FRS | D29: Login | E29: Login with valid registered credentials | F29: User has a registered and active account. | G29: 1. Navigate to the Login page. 2. Enter a valid registered email address. 3. Enter the correct password. 4. Click the Login button. | H29: Email: testuser@example.com | Password: ValidPassword123! | I29: The user is successfully authenticated and redirected to the homepage or account dashboard. | J29: P0 | K29: Positive | L29: Pass | M29: Valid login succeeded; redirected to homepage. | O29: Mona Fathy | P29: 2026-09-16
A30: TC_0029 | B30: TS_002 | C30: FRS | D30: Login | E30: Login with an incorrect password | F30: User has a registered account. | G30: 1. Navigate to the Login page. 2. Enter a valid registered email address. 3. Enter an incorrect password. 4. Click the Login button. | H30: Email: testuser@example.com | Password: WrongPass1! | I30: Login is rejected and an error message 'Invalid email or password' is displayed; the user remains on the login page. | J30: P0 | K30: Negative | L30: Pass | M30: Invalid password correctly rejected with generic error. | O30: Mona Fathy | P30: 2026-09-16
A31: TC_0030 | B31: TS_002 | C31: FRS | D31: Login | E31: Login with an unregistered email address | F31: The email address used is not associated with any account. | G31: 1. Navigate to the Login page. 2. Enter an email address that is not registered. 3. Enter any password. 4. Click the Login button. | H31: Email: notregistered@example.com | Password: AnyPassword1! | I31: Login is rejected and a generic error message 'Invalid email or password' is displayed without revealing whether the email exists. | J31: P0 | K31: Negative | L31: Pass
A32: TC_0031 | B32: TS_002 | C32: FRS | D32: Login | E32: Login with empty Email field | F32: User is on the Login page. | G32: 1. Leave the Email field empty. 2. Enter a valid password. 3. Click the Login button. | H32: Email: (empty) | Password: ValidPassword123! | I32: Login is blocked and a validation message 'Email is required' is displayed. | J32: P0 | K32: Negative - Required Field Validation | L32: Pass
A33: TC_0032 | B33: TS_002 | C33: FRS | D33: Login | E33: Login with empty Password field | F33: User is on the Login page. | G33: 1. Enter a valid registered email address. 2. Leave the Password field empty. 3. Click the Login button. | H33: Email: testuser@example.com | Password: (empty) | I33: Login is blocked and a validation message 'Password is required' is displayed. | J33: P0 | K33: Negative - Required Field Validation | L33: Pass
A34: TC_0033 | B34: TS_002 | C34: FRS | D34: Login | E34: Login with both Email and Password fields empty | F34: User is on the Login page. | G34: 1. Leave both Email and Password fields empty. 2. Click the Login button. | H34: Email: (empty) | Password: (empty) | I34: Login is blocked and validation messages are displayed for both required fields. | J34: P0 | K34: Negative - Required Field Validation | L34: Pass
A35: TC_0034 | B35: TS_002 | C35: FRS | D35: Login | E35: Login with an invalid email format | F35: User is on the Login page. | G35: 1. Enter an email address in an invalid format. 2. Enter any password. 3. Click the Login button. | H35: Email: testuserexample.com | Password: ValidPassword123! | I35: Login is blocked and a validation message 'Please enter a valid email address' is displayed. | J35: P0 | K35: Negative - Field Format Validation | L35: Pass
A36: TC_0035 | B36: TS_002 | C36: FRS | D36: Login | E36: Login with email in different letter casing than registered | F36: User has a registered account with email 'TestUser@example.com'. | G36: 1. Enter the registered email using different casing (e.g., all lowercase). 2. Enter the correct password. 3. Click the Login button. | H36: Email: testuser@example.com | Password: ValidPassword123! | I36: The user is successfully authenticated, confirming email comparison is case-insensitive. | J36: P0 | K36: Equivalence Partitioning | L36: Pass
A37: TC_0036 | B37: TS_002 | C37: FRS | D37: Login | E37: Login with SQL injection payload in the Email field | F37: User is on the Login page. | G37: 1. Enter a SQL injection payload in the Email field. 2. Enter any value in the Password field. 3. Click the Login button. | H37: Email: admin' OR '1'='1 | Password: anything | I37: Login is rejected with a generic invalid credentials message; no database error is exposed and no unauthorized access is granted. | J37: P0 | K37: Security Testing | L37: Pass
A38: TC_0037 | B38: TS_002 | C38: FRS | D38: Login | E38: Login with 'Remember Me' checkbox checked | F38: User has a registered account and the Login page displays a 'Remember Me' checkbox. | G38: 1. Enter valid credentials. 2. Check the 'Remember Me' checkbox. 3. Click the Login button. 4. Close and reopen the browser, then revisit the site. | H38: Email: testuser@example.com | Password: ValidPassword123! | Remember Me: checked | I38: The user remains logged in after closing and reopening the browser, without needing to log in again. | J38: P0 | K38: Functional Testing | L38: Pass
A39: TC_0038 | B39: TS_002 | C39: FRS | D39: Login | E39: Login with 'Remember Me' checkbox unchecked | F39: User has a registered account. | G39: 1. Enter valid credentials. 2. Leave the 'Remember Me' checkbox unchecked. 3. Click the Login button. 4. Close and reopen the browser, then revisit the site. | H39: Email: testuser@example.com | Password: ValidPassword123! | Remember Me: unchecked | I39: The user's session is not persisted; the user is required to log in again after reopening the browser. | J39: P0 | K39: Functional Testing | L39: Pass
A40: TC_0039 | B40: TS_002 | C40: FRS | D40: Login | E40: Verify Password field masks entered characters on Login page | F40: User is on the Login page. | G40: 1. Click into the Password field. 2. Type a password. 3. Observe the displayed characters. | H40: Password: ValidPassword123! | I40: Entered characters are masked by default (shown as dots/asterisks). | J40: P0 | K40: UI Testing | L40: Pass
...

Sheet Test Cases (Simple)
A1: Test Case ID | B1: Test Case Title | C1: Test Steps | D1: Test Data | E1: Expected Result
A2: TC_0001 | B2: Register with valid mandatory data | C2: 1. Navigate to the Registration page. 2. Enter a valid first name, last name, and a unique email address. 3. Enter a password that meets complexity rules. 4. Re-enter the same password in the Confirm Password field. 5. Check the 'I agree to Terms and Conditions' checkbox. 6. Click the Register button. | D2: First Name: Sarah | Last Name: Ahmed | Email: sarah.ahmed01@example.com | Password: Passw0rd!23 | E2: Account is created successfully, a confirmation message is shown, and the user is redirected to the login page or homepage as a logged-in user.
A3: TC_0002 | B3: Register with empty First Name field | C3: 1. Leave the First Name field empty. 2. Fill in all other required fields with valid data. 3. Click the Register button. | D3: First Name: (empty) | Last Name: Hassan | Email: hassan.t@example.com | Password: Passw0rd!23 | E3: Registration is blocked and an inline validation message 'First name is required' is displayed under the First Name field.
A4: TC_0003 | B4: Register with empty Last Name field | C4: 1. Leave the Last Name field empty. 2. Fill in all other required fields with valid data. 3. Click the Register button. | D4: First Name: Omar | Last Name: (empty) | Email: omar.k@example.com | Password: Passw0rd!23 | E4: Registration is blocked and an inline validation message 'Last name is required' is displayed under the Last Name field.
A5: TC_0004 | B5: Register with empty Email field | C5: 1. Leave the Email field empty. 2. Fill in all other required fields with valid data. 3. Click the Register button. | D5: Email: (empty) | E5: Registration is blocked and an inline validation message 'Email is required' is displayed under the Email field.
A6: TC_0005 | B6: Register with empty Password field | C6: 1. Leave the Password field empty. 2. Fill in all other required fields with valid data. 3. Click the Register button. | D6: Password: (empty) | E6: Registration is blocked and an inline validation message 'Password is required' is displayed under the Password field.
A7: TC_0006 | B7: Register with empty Confirm Password field | C7: 1. Enter a valid password in the Password field. 2. Leave the Confirm Password field empty. 3. Click the Register button. | D7: Password: Passw0rd!23 | Confirm Password: (empty) | E7: Registration is blocked and a validation message 'Please confirm your password' is displayed.
A8: TC_0007 | B8: Register with invalid email format - missing @ symbol | C8: 1. Fill in all fields with valid data. 2. Enter an email address without an '@' symbol. 3. Click the Register button. | D8: Email: sarahexample.com | E8: Registration is blocked and a validation message 'Please enter a valid email address' is displayed.
A9: TC_0008 | B9: Register with invalid email format - missing domain | C9: 1. Fill in all fields with valid data. 2. Enter an email address without a domain after the '@' symbol. 3. Click the Register button. | D9: Email: sarah.ahmed@ | E9: Registration is blocked and a validation message 'Please enter a valid email address' is displayed.
A10: TC_0009 | B10: Register with an already registered email address | C10: 1. Navigate to the Registration page. 2. Fill in the form using an email address that is already registered. 3. Click the Register button. | D10: Email: existing.user@example.com | E10: Registration is blocked and an error message 'An account with this email already exists' is displayed, with a suggestion to log in instead.
A11: TC_0010 | B11: Register with password shorter than minimum allowed length | C11: 1. Fill in all fields with valid data. 2. Enter a password with 7 characters. 3. Click the Register button. | D11: Password: Pas1!aB (7 characters) | E11: Registration is blocked and a validation message 'Password must be at least 8 characters long' is displayed.
A12: TC_0011 | B12: Register with password at exact minimum allowed length | C12: 1. Fill in all fields with valid data. 2. Enter a password with exactly 8 characters meeting complexity rules. 3. Click the Register button. | D12: Password: Pass1!aB (8 characters) | E12: Password is accepted and the account is registered successfully.
... A272: TC_0271 | B272: Logout successfully from the My Account page | C272: 1. Navigate to the My Account page. 2. Click the Logout option from the account menu. | D272: N/A | E272: The user is logged out successfully and redirected to the homepage or login page, with the session terminated.

Sheet Test Execution
A1: Test Case ID | B1: Test Scenario ID | C1: Module | D1: Priority | E1: Status | F1: Executed By | G1: Execution Date | H1: Defect ID | I1: Comments
A2: ='Test Cases'!A2 -> TC_0001 | B2: ='Test Cases'!B2 -> TS_001 | C2: ='Test Cases'!D2 -> Register | D2: ='Test Cases'!J2 -> P0 | E2: ='Test Cases'!L2 -> Pass | F2: ='Test Cases'!O2 -> Ali Hassan | G2: ='Test Cases'!P2 -> 2026-09-15 | H2: ='Test Cases'!N2 -> 0
A3: ='Test Cases'!A3 -> TC_0002 | B3: ='Test Cases'!B3 -> TS_001 | C3: ='Test Cases'!D3 -> Register | D3: ='Test Cases'!J3 -> P0 | E3: ='Test Cases'!L3 -> Pass | F3: ='Test Cases'!O3 -> Mona Fathy | G3: ='Test Cases'!P3 -> 2026-09-15 | H3: ='Test Cases'!N3 -> 0
A4: ='Test Cases'!A4 -> TC_0003 | B4: ='Test Cases'!B4 -> TS_001 | C4: ='Test Cases'!D4 -> Register | D4: ='Test Cases'!J4 -> P0 | E4: ='Test Cases'!L4 -> Pass | F4: ='Test Cases'!O4 -> 0 | G4: ='Test Cases'!P4 -> 0 | H4: ='Test Cases'!N4 -> 0
A5: ='Test Cases'!A5 -> TC_0004 | B5: ='Test Cases'!B5 -> TS_001 | C5: ='Test Cases'!D5 -> Register | D5: ='Test Cases'!J5 -> P0 | E5: ='Test Cases'!L5 -> Pass | F5: ='Test Cases'!O5 -> 0 | G5: ='Test Cases'!P5 -> 0 | H5: ='Test Cases'!N5 -> 0
A6: ='Test Cases'!A6 -> TC_0005 | B6: ='Test Cases'!B6 -> TS_001 | C6: ='Test Cases'!D6 -> Register | D6: ='Test Cases'!J6 -> P0 | E6: ='Test Cases'!L6 -> Pass | F6: ='Test Cases'!O6 -> 0 | G6: ='Test Cases'!P6 -> 0 | H6: ='Test Cases'!N6 -> 0
A7: ='Test Cases'!A7 -> TC_0006 | B7: ='Test Cases'!B7 -> TS_001 | C7: ='Test Cases'!D7 -> Register | D7: ='Test Cases'!J7 -> P0 | E7: ='Test Cases'!L7 -> Pass | F7: ='Test Cases'!O7 -> 0 | G7: ='Test Cases'!P7 -> 0 | H7: ='Test Cases'!N7 -> 0
A8: ='Test Cases'!A8 -> TC_0007 | B8: ='Test Cases'!B8 -> TS_001 | C8: ='Test Cases'!D8 -> Register | D8: ='Test Cases'!J8 -> P0 | E8: ='Test Cases'!L8 -> Pass | F8: ='Test Cases'!O8 -> 0 | G8: ='Test Cases'!P8 -> 0 | H8: ='Test Cases'!N8 -> 0
A9: ='Test Cases'!A9 -> TC_0008 | B9: ='Test Cases'!B9 -> TS_001 | C9: ='Test Cases'!D9 -> Register | D9: ='Test Cases'!J9 -> P0 | E9: ='Test Cases'!L9 -> Pass | F9: ='Test Cases'!O9 -> 0 | G9: ='Test Cases'!P9 -> 0 | H9: ='Test Cases'!N9 -> 0
A10: ='Test Cases'!A10 -> TC_0009 | B10: ='Test Cases'!B10 -> TS_001 | C10: ='Test Cases'!D10 -> Register | D10: ='Test Cases'!J10 -> P0 | E10: ='Test Cases'!L10 -> Fail | F10: ='Test Cases'!O10 -> Mona Fathy | G10: ='Test Cases'!P10 -> 2026-09-15 | H10: ='Test Cases'!N10 -> BUG_001
A11: ='Test Cases'!A11 -> TC_0010 | B11: ='Test Cases'!B11 -> TS_001 | C11: ='Test Cases'!D11 -> Register | D11: ='Test Cases'!J11 -> P0 | E11: ='Test Cases'!L11 -> Not Run | F11: ='Test Cases'!O11 -> 0 | G11: ='Test Cases'!P11 -> 0 | H11: ='Test Cases'!N11 -> 0
A12: ='Test Cases'!A12 -> TC_0011 | B12: ='Test Cases'!B12 -> TS_001 | C12: ='Test Cases'!D12 -> Register | D12: ='Test Cases'!J12 -> P0 | E12: ='Test Cases'!L12 -> Not Run | F12: ='Test Cases'!O12 -> 0 | G12: ='Test Cases'!P12 -> 0 | H12: ='Test Cases'!N12 -> 0
A13: ='Test Cases'!A13 -> TC_0012 | B13: ='Test Cases'!B13 -> TS_001 | C13: ='Test Cases'!D13 -> Register | D13: ='Test Cases'!J13 -> P0 | E13: ='Test Cases'!L13 -> Not Run | F13: ='Test Cases'!O13 -> 0 | G13: ='Test Cases'!P13 -> 0 | H13: ='Test Cases'!N13 -> 0
... A272: ='Test Cases'!A272 -> TC_0271 | B272: ='Test Cases'!B272 -> TS_013 | C272: ='Test Cases'!D272 -> My Account | D272: ='Test Cases'!J272 -> P2 | E272: ='Test Cases'!L272 -> Not Run | F272: ='Test Cases'!O272 -> 0 | G272: ='Test Cases'!P272 -> 0 | H272: ='Test Cases'!N272 -> 0

Sheet Bug Tracker
A1: Bug ID | B1: Summary | C1: Test Case ID | D1: Module | E1: Severity | F1: Priority | G1: Status | H1: Environment | I1: Steps to Reproduce | J1: Expected Result | K1: Actual Result | L1: Assigned To | M1: Created Date | N1: Closed Date
A2: =IF(B2="","","BUG_"&TEXT(ROW()-1,"000")) -> BUG_001 | B2: Duplicate account created with an already-registered email | C2: TC_0009 | D2: Register | E2: High | F2: P0 | G2: Open | H2: Staging - Chrome 128 | I2: 1. Register a new account using an email that already exists in the system. 2. Submit the registration form. | J2: Registration should be blocked with an 'account already exists' error message. | K2: The account was created successfully with no error, resulting in a duplicate email in the database. | L2: Dev Team - Backend | M2: 2026-09-15
A3: =IF(B3="","","BUG_"&TEXT(ROW()-1,"000")) -> BUG_002 | B3: Account lockout not enforced after repeated failed login attempts | C3: TC_0042 | D3: Login | E3: Critical | F3: P0 | G3: Open | H3: Staging - Chrome 128 | I3: 1. Attempt to log in with an incorrect password 5 times consecutively. 2. Attempt a 6th login. | J3: The account should be temporarily locked after 5 failed attempts, with a lockout message on the 6th attempt. | K3: No lockout occurred; the 6th attempt was processed as a normal login retry. | L3: Dev Team - Backend | M3: 2026-09-16
A4: =IF(B4="","","BUG_"&TEXT(ROW()-1,"000")) -> BUG_003 | B4: Search field vulnerable to SQL injection payload causing server error | C4: TC_0100 | D4: Search | E4: Critical | F4: P1 | G4: New | H4: Staging - Chrome 128 | I4: 1. Enter a SQL injection payload ( ' OR '1'='1 ) into the search bar. 2. Submit the search. | J4: The input should be safely handled as plain text, returning no results without any server error. | K4: The server returned an HTTP 500 error page instead of handling the input safely. | L4: Dev Team - Backend | M4: 2026-09-17
A5: =IF(B5="","","BUG_"&TEXT(ROW()-1,"000")) -> BUG_004 | B5: Expired coupon code incorrectly accepted and discount applied | C5: TC_0225 | D5: Shopping Cart | E5: High | F5: P1 | G5: Open | H5: Staging - Chrome 128 | I5: 1. Add items to the cart. 2. Apply a coupon code that has passed its expiration date. | J5: The expired coupon should be rejected with an 'invalid or expired coupon' message. | K5: The expired coupon was accepted and the discount was applied to the order total. | L5: Dev Team - Backend | M5: 2026-09-19
A6: =IF(B6="","","BUG_"&TEXT(ROW()-1,"000")) -> BUG_005 | B6: Duplicate order created on rapid double-click of Place Order | C6: TC_0258 | D6: Checkout | E6: Critical | F6: P1 | G6: New | H6: Staging - Chrome 128 | I6: 1. Complete all checkout steps with valid data. 2. Rapidly double-click the 'Place Order' button before the page responds. | J6: Only one order should be created; the button should disable after the first click. | K6: Two separate orders were created for a single checkout attempt, resulting in a duplicate charge risk. | L6: Dev Team - Frontend | M6: 2026-09-20
A7: =IF(B7="","","BUG_"&TEXT(ROW()-1,"000"))
A8: =IF(B8="","","BUG_"&TEXT(ROW()-1,"000"))
A9: =IF(B9="","","BUG_"&TEXT(ROW()-1,"000"))
A10: =IF(B10="","","BUG_"&TEXT(ROW()-1,"000"))
A11: =IF(B11="","","BUG_"&TEXT(ROW()-1,"000"))
A12: =IF(B12="","","BUG_"&TEXT(ROW()-1,"000"))
A13: =IF(B13="","","BUG_"&TEXT(ROW()-1,"000"))
A14: =IF(B14="","","BUG_"&TEXT(ROW()-1,"000"))
A15: =IF(B15="","","BUG_"&TEXT(ROW()-1,"000"))
A16: =IF(B16="","","BUG_"&TEXT(ROW()-1,"000"))
A17: =IF(B17="","","BUG_"&TEXT(ROW()-1,"000"))
A18: =IF(B18="","","BUG_"&TEXT(ROW()-1,"000"))
... A61: =IF(B61="","","BUG_"&TEXT(ROW()-1,"000"))

Sheet Requirements
A1: Requirement ID | B1: Reference | C1: Requirement / Feature | D1: Related Test Scenario | E1: Priority
A2: REQ_001 | B2: FRS | C2: The system shall allow a new user to create an account by providing mandatory registration details, validating all inputs, and preventing duplicate accounts. | D2: TS_001 | E2: P0
A3: REQ_002 | B3: FRS | C3: The system shall allow a registered user to securely authenticate using their email and password, including session and lockout handling. | D3: TS_002 | E3: P0
A4: REQ_003 | B4: FRS | C4: The system shall allow an authenticated user to securely terminate their session at any time. | D4: TS_003 | E4: P0
A5: REQ_004 | B5: FRS | C5: The system shall allow a user who forgot their password to securely reset it via a time-limited, single-use email link. | D5: TS_004 | E5: P2
A6: REQ_005 | B6: FRS | C6: The system shall allow users to search the product catalog by keyword, SKU, or partial match, with sorting, filtering, and pagination. | D6: TS_005 | E6: P1
A7: REQ_006 | B7: FRS | C7: The system shall allow users to select multiple products and view a side-by-side comparison of their attributes. | D7: TS_006 | E7: P4
A8: REQ_007 | B8: FRS | C8: The system shall display complete, accurate product information including price, images, variants, stock, and reviews on the Product Display Page. | D8: TS_007 | E8: P1
A9: REQ_008 | B9: FRS | C9: The system shall allow users to add available products to their shopping cart with the desired quantity and variant. | D9: TS_008 | E9: P1
A10: REQ_009 | B10: FRS | C10: The system shall allow logged-in users to save products of interest to a persistent wishlist for later purchase. | D10: TS_009 | E10: P4
A11: REQ_010 | B11: FRS | C11: The system shall allow users to review, modify, and accurately price the contents of their shopping cart prior to checkout. | D11: TS_010 | E11: P1
A12: REQ_011 | B12: FRS | C12: The system shall present an engaging, functional homepage that provides entry points to key site sections and promotions. | D12: TS_011 | E12: P2
... A14: REQ_013 | B14: FRS | C14: The system shall allow authenticated users to view and manage their profile, password, and order history. | D14: TS_013 | E14: P2

Sheet Dashboard
B2: Manual Testing — QA Dashboard
B3: E-Commerce Web Application | Live metrics computed from the 'Test Cases' sheet
B5: Execution Summary
B6: Total Test Cases | C6: Not Run | D6: Pass | E6: Fail | F6: Blocked | G6: Pass Rate | H6: Fail Rate
B7: =COUNTA('Test Cases'!$L$2:$L$272) -> 271 | C7: =COUNTIF('Test Cases'!$L$2:$L$272,"Not Run") -> 196 | D7: =COUNTIF('Test Cases'!$L$2:$L$272,"Pass") -> 69 | E7: =COUNTIF('Test Cases'!$L$2:$L$272,"Fail") -> 5 | F7: =COUNTIF('Test Cases'!$L$2:$L$272,"Blocked") -> 1 | G7: =IFERROR(D7/B7,0) -> 0.25461255 | H7: =IFERROR(E7/B7,0) -> 0.018450185
B10: Test Cases by Priority | E10: Test Cases by Module
B11: Priority | C11: Count | E11: Module | F11: Count
B12: P0 | C12: =COUNTIF('Test Cases'!$J$2:$J$272,"P0") -> 61 | E12: Register | F12: =COUNTIF('Test Cases'!$D$2:$D$272,"Register") -> 27
B13: P1 | C13: =COUNTIF('Test Cases'!$J$2:$J$272,"P1") -> 121 | E13: Login | F13: =COUNTIF('Test Cases'!$D$2:$D$272,"Login") -> 23
B14: P2 | C14: =COUNTIF('Test Cases'!$J$2:$J$272,"P2") -> 44 | E14: Logout | F14: =COUNTIF('Test Cases'!$D$2:$D$272,"Logout") -> 11
B15: P4 | C15: =COUNTIF('Test Cases'!$J$2:$J$272,"P4") -> 45 | E15: Forgot Password | F15: =COUNTIF('Test Cases'!$D$2:$D$272,"Forgot Password") -> 25
E16: Search | F16: =COUNTIF('Test Cases'!$D$2:$D$272,"Search") -> 22
E17: Product Compare | F17: =COUNTIF('Test Cases'!$D$2:$D$272,"Product Compare") -> 24
E18: Product Display Page | F18: =COUNTIF('Test Cases'!$D$2:$D$272,"Product Display Page") -> 37
E19: Add to Cart | F19: =COUNTIF('Test Cases'!$D$2:$D$272,"Add to Cart") -> 9
E20: Wish List | F20: =COUNTIF('Test Cases'!$D$2:$D$272,"Wish List") -> 21
E21: Shopping Cart | F21: =COUNTIF('Test Cases'!$D$2:$D$272,"Shopping Cart") -> 33
E22: Home Page | F22: =COUNTIF('Test Cases'!$D$2:$D$272,"Home Page") -> 10
E23: Checkout | F23: =COUNTIF('Test Cases'!$D$2:$D$272,"Checkout") -> 20
E24: My Account | F24: =COUNTIF('Test Cases'!$D$2:$D$272,"My Account") -> 9
B27: Test Execution Status
B28: Status | C28: Count
B29: Not Run | C29: =COUNTIF('Test Cases'!$L$2:$L$272,"Not Run") -> 196
B30: Pass | C30: =COUNTIF('Test Cases'!$L$2:$L$272,"Pass") -> 69
B31: Fail | C31: =COUNTIF('Test Cases'!$L$2:$L$272,"Fail") -> 5
B32: Blocked | C32: =COUNTIF('Test Cases'!$L$2:$L$272,"Blocked") -> 1
B33: N/A | C33: =COUNTIF('Test Cases'!$L$2:$L$272,"N/A") -> 0
B36: Charts
